Workbook

Sheet Settings
A1: Settings for the dashboard
A3: Setting | B3: Value
A4: Lookback window (weeks) | B4: 1
A5: Lookback start date | B5: =TODAY()-(B4*7)
A6: Buyback flag threshold (% shares out decline) | B6: -1e-05
A7: Volume spike multiple (x 30D avg) | B7: 2
A8: Dividend flag rule
A9: Split/Rights flag rule | B9: Any occurrence within lookback window
A11: Legend
A12: Yellow fill / blue text | B12: Input Cell
A13: Black text | B13: Formula
A14: Green text | B14: Linked Cell
A15: Orange fill | B15: Cells using Bloomberg Formula
A16: Red fill on a Flag cell | B16: Significant activity detected in the lookback window

Sheet STI30 Dashboard
A1: CORPORATE ACTIONS DASHBOARD — STI TOP 30
A3: Ticker | B3: Name | C3: Buyback Flag | D3: Volume Flag | E3: Dividend Flag | F3: Split/Rights Flag | H3: SHARE BUYBACK AGGREGATOR
A4: ='STI30 Universe'!A5 | B4: ='STI30 Universe'!B5 | C4: ='STI30 Buybacks'!F4 | D4: ='STI30 Buybacks'!J4 | E4: ='STI30 Dividends'!H4 | F4: ='STI30 Offerings'!J4 | H4: Number of Trading Days of Lookback | L4: 30
A5: ='STI30 Universe'!A6 | B5: ='STI30 Universe'!B6 | C5: ='STI30 Buybacks'!F5 | D5: ='STI30 Buybacks'!J5 | E5: ='STI30 Dividends'!H5 | F5: ='STI30 Offerings'!J5 | H5: Company Ticker | L5: ST SP Equity
A6: ='STI30 Universe'!A7 | B6: ='STI30 Universe'!B7 | C6: ='STI30 Buybacks'!F6 | D6: ='STI30 Buybacks'!J6 | E6: ='STI30 Dividends'!H6 | F6: ='STI30 Offerings'!J6 | H6: Company Name | L6: =_xll.BDP(L5,"NAME")
A7: ='STI30 Universe'!A8 | B7: ='STI30 Universe'!B8 | C7: ='STI30 Buybacks'!F7 | D7: ='STI30 Buybacks'!J7 | E7: ='STI30 Dividends'!H7 | F7: ='STI30 Offerings'!J7 | H7: Buyback Amount | L7: =_xll.BQL(L5, "sum(share_buybacks(effective_date=range(-" & L4 &"D, 0D)))", "currency", "SGD")
A8: ='STI30 Universe'!A9 | B8: ='STI30 Universe'!B9 | C8: ='STI30 Buybacks'!F8 | D8: ='STI30 Buybacks'!J8 | E8: ='STI30 Dividends'!H8 | F8: ='STI30 Offerings'!J8
A9: ='STI30 Universe'!A10 | B9: ='STI30 Universe'!B10 | C9: ='STI30 Buybacks'!F9 | D9: ='STI30 Buybacks'!J9 | E9: ='STI30 Dividends'!H9 | F9: ='STI30 Offerings'!J9
A10: ='STI30 Universe'!A11 | B10: ='STI30 Universe'!B11 | C10: ='STI30 Buybacks'!F10 | D10: ='STI30 Buybacks'!J10 | E10: ='STI30 Dividends'!H10 | F10: ='STI30 Offerings'!J10
A11: ='STI30 Universe'!A12 | B11: ='STI30 Universe'!B12 | C11: ='STI30 Buybacks'!F11 | D11: ='STI30 Buybacks'!J11 | E11: ='STI30 Dividends'!H11 | F11: ='STI30 Offerings'!J11
A12: ='STI30 Universe'!A13 | B12: ='STI30 Universe'!B13 | C12: ='STI30 Buybacks'!F12 | D12: ='STI30 Buybacks'!J12 | E12: ='STI30 Dividends'!H12 | F12: ='STI30 Offerings'!J12
A13: ='STI30 Universe'!A14 | B13: ='STI30 Universe'!B14 | C13: ='STI30 Buybacks'!F13 | D13: ='STI30 Buybacks'!J13 | E13: ='STI30 Dividends'!H13 | F13: ='STI30 Offerings'!J13
A14: ='STI30 Universe'!A15 | B14: ='STI30 Universe'!B15 | C14: ='STI30 Buybacks'!F14 | D14: ='STI30 Buybacks'!J14 | E14: ='STI30 Dividends'!H14 | F14: ='STI30 Offerings'!J14
A15: ='STI30 Universe'!A16 | B15: ='STI30 Universe'!B16 | C15: ='STI30 Buybacks'!F15 | D15: ='STI30 Buybacks'!J15 | E15: ='STI30 Dividends'!H15 | F15: ='STI30 Offerings'!J15
A16: ='STI30 Universe'!A17 | B16: ='STI30 Universe'!B17 | C16: ='STI30 Buybacks'!F16 | D16: ='STI30 Buybacks'!J16 | E16: ='STI30 Dividends'!H16 | F16: ='STI30 Offerings'!J16
A17: ='STI30 Universe'!A18 | B17: ='STI30 Universe'!B18 | C17: ='STI30 Buybacks'!F17 | D17: ='STI30 Buybacks'!J17 | E17: ='STI30 Dividends'!H17 | F17: ='STI30 Offerings'!J17
A18: ='STI30 Universe'!A19 | B18: ='STI30 Universe'!B19 | C18: ='STI30 Buybacks'!F18 | D18: ='STI30 Buybacks'!J18 | E18: ='STI30 Dividends'!H18 | F18: ='STI30 Offerings'!J18
A19: ='STI30 Universe'!A20 | B19: ='STI30 Universe'!B20 | C19: ='STI30 Buybacks'!F19 | D19: ='STI30 Buybacks'!J19 | E19: ='STI30 Dividends'!H19 | F19: ='STI30 Offerings'!J19
... A33: ='STI30 Universe'!A34 | B33: ='STI30 Universe'!B34 | C33: ='STI30 Buybacks'!F33 | D33: ='STI30 Buybacks'!J33 | E33: ='STI30 Dividends'!H33 | F33: ='STI30 Offerings'!J33

Sheet STI30 Universe
A1: Universe — STI Top 30 Constituents
A3: Ticker (Bloomberg) | B3: Company Name | C3: Market Cap | D3: GICS Sector | E3: Primary Exchange
A4: (static snapshot from source Universe tab — re-run your BQL universe pull to refresh tickers/names/sectors)
A5: DBS SP Equity | B5: DBS Group Holdings Ltd | C5: 2.2069432e+11 | D5: Financials | E5: Singapore
A6: OCBC SP Equity | B6: Oversea-Chinese Banking Corp L | C6: 1.4362209e+11 | D6: Financials | E6: Singapore
A7: ST SP Equity | B7: Singapore Telecommunications L | C7: 7.2707905e+10 | D7: Communication Services | E7: Singapore
A8: UOB SP Equity | B8: United Overseas Bank Ltd | C8: 7.0135384e+10 | D8: Financials | E8: Singapore
A9: STE SP Equity | B9: Singapore Technologies Enginee | C9: 3.1895144e+10 | D9: Industrials | E9: Singapore
A10: SGX SP Equity | B10: Singapore Exchange Ltd | C10: 2.4425939e+10 | D10: Financials | E10: Singapore
A11: WIL SP Equity | B11: Wilmar International Ltd | C11: 2.3101907e+10 | D11: Consumer Staples | E11: Singapore
A12: SIA SP Equity | B12: Singapore Airlines Ltd | C12: 2.0877285e+10 | D12: Industrials | E12: Singapore
A13: KEP SP Equity | B13: Keppel Ltd | C13: 2.0332637e+10 | D13: Industrials | E13: Singapore
A14: YZJSGD SP Equity | B14: Yangzijiang Shipbuilding Holdi | C14: 2.0189573e+10 | D14: Industrials | E14: Singapore
A15: CICT SP Equity | B15: CapitaLand Integrated Commerci | C15: 1.818083e+10 | D15: Real Estate | E15: Singapore
A16: CLI SP Equity | B16: CapitaLand Investment Ltd/Sing | C16: 1.3132988e+10 | D16: Real Estate | E16: Singapore
... A32: FLT SP Equity | B32: Frasers Logistics & Commercial | C32: 3.4087051e+09 | D32: Real Estate | E32: Singapore
A33: JM SP Equity | B33: ADD MANUALLY: Jardine Matheson Holdings Ltd
A34: HKL SP Equity | B34: ADD MANUALLY: Hongkong Land Holdings Ltd

Sheet STI30 Buybacks
A1: Share Buyback Tracker — STI Top 30
A3: Ticker | B3: Company Name | C3: Shares Out Today | D3: =CONCATENATE("Shares Out ",Settings!B4, IF(Settings!B4>1," Wks Ago"," Wk Ago")) | E3: % Change | F3: Buyback Flag | G3: Avg Vol (30D) | H3: Volume — Today | I3: Vol vs Avg (x) | J3: Volume Flag
A4: ='STI30 Universe'!A5 | B4: =IFERROR(_xll.BDP(A4,"NAME"),"") | C4: =IFERROR(_xll.BDP(A4,"EQY_SH_OUT"),NA()) | D4: =IFERROR(_xll.BDH(A4,"EQY_SH_OUT","-"&Settings!$B$4&"AW","-"&Settings!$B$4&"AW","days=a","fill=p"),NA()) | E4: =IFERROR((C4-D4)/D4,NA()) | F4: =IF(ISNUMBER(E4),IF(E4<=Settings!$B$6,"BUYBACK ACTIVITY",""),"") | G4: =IFERROR(_xll.BDP(A4,"VOLUME_AVG_30D"),NA()) | H4: =IFERROR(_xll.BDP(A4,"PX_VOLUME"),NA()) | I4: =IFERROR(H4/G4,NA()) | J4: =IF(ISNUMBER(I4),IF(I4>=Settings!$B$7,"VOL SPIKE",""),"")
A5: ='STI30 Universe'!A6 | B5: =IFERROR(_xll.BDP(A5,"NAME"),"") | C5: =IFERROR(_xll.BDP(A5,"EQY_SH_OUT"),NA()) | D5: =IFERROR(_xll.BDH(A5,"EQY_SH_OUT","-"&Settings!$B$4&"AW","-"&Settings!$B$4&"AW","days=a","fill=p"),NA()) | E5: =IFERROR((C5-D5)/D5,NA()) | F5: =IF(ISNUMBER(E5),IF(E5<=Settings!$B$6,"BUYBACK ACTIVITY",""),"") | G5: =IFERROR(_xll.BDP(A5,"VOLUME_AVG_30D"),NA()) | H5: =IFERROR(_xll.BDP(A5,"PX_VOLUME"),NA()) | I5: =IFERROR(H5/G5,NA()) | J5: =IF(ISNUMBER(I5),IF(I5>=Settings!$B$7,"VOL SPIKE",""),"")
A6: ='STI30 Universe'!A7 | B6: =IFERROR(_xll.BDP(A6,"NAME"),"") | C6: =IFERROR(_xll.BDP(A6,"EQY_SH_OUT"),NA()) | D6: =IFERROR(_xll.BDH(A6,"EQY_SH_OUT","-"&Settings!$B$4&"AW","-"&Settings!$B$4&"AW","days=a","fill=p"),NA()) | E6: =IFERROR((C6-D6)/D6,NA()) | F6: =IF(ISNUMBER(E6),IF(E6<=Settings!$B$6,"BUYBACK ACTIVITY",""),"") | G6: =IFERROR(_xll.BDP(A6,"VOLUME_AVG_30D"),NA()) | H6: =IFERROR(_xll.BDP(A6,"PX_VOLUME"),NA()) | I6: =IFERROR(H6/G6,NA()) | J6: =IF(ISNUMBER(I6),IF(I6>=Settings!$B$7,"VOL SPIKE",""),"")
A7: ='STI30 Universe'!A8 | B7: =IFERROR(_xll.BDP(A7,"NAME"),"") | C7: =IFERROR(_xll.BDP(A7,"EQY_SH_OUT"),NA()) | D7: =IFERROR(_xll.BDH(A7,"EQY_SH_OUT","-"&Settings!$B$4&"AW","-"&Settings!$B$4&"AW","days=a","fill=p"),NA()) | E7: =IFERROR((C7-D7)/D7,NA()) | F7: =IF(ISNUMBER(E7),IF(E7<=Settings!$B$6,"BUYBACK ACTIVITY",""),"") | G7: =IFERROR(_xll.BDP(A7,"VOLUME_AVG_30D"),NA()) | H7: =IFERROR(_xll.BDP(A7,"PX_VOLUME"),NA()) | I7: =IFERROR(H7/G7,NA()) | J7: =IF(ISNUMBER(I7),IF(I7>=Settings!$B$7,"VOL SPIKE",""),"")
A8: ='STI30 Universe'!A9 | B8: =IFERROR(_xll.BDP(A8,"NAME"),"") | C8: =IFERROR(_xll.BDP(A8,"EQY_SH_OUT"),NA()) | D8: =IFERROR(_xll.BDH(A8,"EQY_SH_OUT","-"&Settings!$B$4&"AW","-"&Settings!$B$4&"AW","days=a","fill=p"),NA()) | E8: =IFERROR((C8-D8)/D8,NA()) | F8: =IF(ISNUMBER(E8),IF(E8<=Settings!$B$6,"BUYBACK ACTIVITY",""),"") | G8: =IFERROR(_xll.BDP(A8,"VOLUME_AVG_30D"),NA()) | H8: =IFERROR(_xll.BDP(A8,"PX_VOLUME"),NA()) | I8: =IFERROR(H8/G8,NA()) | J8: =IF(ISNUMBER(I8),IF(I8>=Settings!$B$7,"VOL SPIKE",""),"")
A9: ='STI30 Universe'!A10 | B9: =IFERROR(_xll.BDP(A9,"NAME"),"") | C9: =IFERROR(_xll.BDP(A9,"EQY_SH_OUT"),NA()) | D9: =IFERROR(_xll.BDH(A9,"EQY_SH_OUT","-"&Settings!$B$4&"AW","-"&Settings!$B$4&"AW","days=a","fill=p"),NA()) | E9: =IFERROR((C9-D9)/D9,NA()) | F9: =IF(ISNUMBER(E9),IF(E9<=Settings!$B$6,"BUYBACK ACTIVITY",""),"") | G9: =IFERROR(_xll.BDP(A9,"VOLUME_AVG_30D"),NA()) | H9: =IFERROR(_xll.BDP(A9,"PX_VOLUME"),NA()) | I9: =IFERROR(H9/G9,NA()) | J9: =IF(ISNUMBER(I9),IF(I9>=Settings!$B$7,"VOL SPIKE",""),"")
A10: ='STI30 Universe'!A11 | B10: =IFERROR(_xll.BDP(A10,"NAME"),"") | C10: =IFERROR(_xll.BDP(A10,"EQY_SH_OUT"),NA()) | D10: =IFERROR(_xll.BDH(A10,"EQY_SH_OUT","-"&Settings!$B$4&"AW","-"&Settings!$B$4&"AW","days=a","fill=p"),NA()) | E10: =IFERROR((C10-D10)/D10,NA()) | F10: =IF(ISNUMBER(E10),IF(E10<=Settings!$B$6,"BUYBACK ACTIVITY",""),"") | G10: =IFERROR(_xll.BDP(A10,"VOLUME_AVG_30D"),NA()) | H10: =IFERROR(_xll.BDP(A10,"PX_VOLUME"),NA()) | I10: =IFERROR(H10/G10,NA()) | J10: =IF(ISNUMBER(I10),IF(I10>=Settings!$B$7,"VOL SPIKE",""),"")
A11: ='STI30 Universe'!A12 | B11: =IFERROR(_xll.BDP(A11,"NAME"),"") | C11: =IFERROR(_xll.BDP(A11,"EQY_SH_OUT"),NA()) | D11: =IFERROR(_xll.BDH(A11,"EQY_SH_OUT","-"&Settings!$B$4&"AW","-"&Settings!$B$4&"AW","days=a","fill=p"),NA()) | E11: =IFERROR((C11-D11)/D11,NA()) | F11: =IF(ISNUMBER(E11),IF(E11<=Settings!$B$6,"BUYBACK ACTIVITY",""),"") | G11: =IFERROR(_xll.BDP(A11,"VOLUME_AVG_30D"),NA()) | H11: =IFERROR(_xll.BDP(A11,"PX_VOLUME"),NA()) | I11: =IFERROR(H11/G11,NA()) | J11: =IF(ISNUMBER(I11),IF(I11>=Settings!$B$7,"VOL SPIKE",""),"")
A12: ='STI30 Universe'!A13 | B12: =IFERROR(_xll.BDP(A12,"NAME"),"") | C12: =IFERROR(_xll.BDP(A12,"EQY_SH_OUT"),NA()) | D12: =IFERROR(_xll.BDH(A12,"EQY_SH_OUT","-"&Settings!$B$4&"AW","-"&Settings!$B$4&"AW","days=a","fill=p"),NA()) | E12: =IFERROR((C12-D12)/D12,NA()) | F12: =IF(ISNUMBER(E12),IF(E12<=Settings!$B$6,"BUYBACK ACTIVITY",""),"") | G12: =IFERROR(_xll.BDP(A12,"VOLUME_AVG_30D"),NA()) | H12: =IFERROR(_xll.BDP(A12,"PX_VOLUME"),NA()) | I12: =IFERROR(H12/G12,NA()) | J12: =IF(ISNUMBER(I12),IF(I12>=Settings!$B$7,"VOL SPIKE",""),"")
A13: ='STI30 Universe'!A14 | B13: =IFERROR(_xll.BDP(A13,"NAME"),"") | C13: =IFERROR(_xll.BDP(A13,"EQY_SH_OUT"),NA()) | D13: =IFERROR(_xll.BDH(A13,"EQY_SH_OUT","-"&Settings!$B$4&"AW","-"&Settings!$B$4&"AW","days=a","fill=p"),NA()) | E13: =IFERROR((C13-D13)/D13,NA()) | F13: =IF(ISNUMBER(E13),IF(E13<=Settings!$B$6,"BUYBACK ACTIVITY",""),"") | G13: =IFERROR(_xll.BDP(A13,"VOLUME_AVG_30D"),NA()) | H13: =IFERROR(_xll.BDP(A13,"PX_VOLUME"),NA()) | I13: =IFERROR(H13/G13,NA()) | J13: =IF(ISNUMBER(I13),IF(I13>=Settings!$B$7,"VOL SPIKE",""),"")
A14: ='STI30 Universe'!A15 | B14: =IFERROR(_xll.BDP(A14,"NAME"),"") | C14: =IFERROR(_xll.BDP(A14,"EQY_SH_OUT"),NA()) | D14: =IFERROR(_xll.BDH(A14,"EQY_SH_OUT","-"&Settings!$B$4&"AW","-"&Settings!$B$4&"AW","days=a","fill=p"),NA()) | E14: =IFERROR((C14-D14)/D14,NA()) | F14: =IF(ISNUMBER(E14),IF(E14<=Settings!$B$6,"BUYBACK ACTIVITY",""),"") | G14: =IFERROR(_xll.BDP(A14,"VOLUME_AVG_30D"),NA()) | H14: =IFERROR(_xll.BDP(A14,"PX_VOLUME"),NA()) | I14: =IFERROR(H14/G14,NA()) | J14: =IF(ISNUMBER(I14),IF(I14>=Settings!$B$7,"VOL SPIKE",""),"")
A15: ='STI30 Universe'!A16 | B15: =IFERROR(_xll.BDP(A15,"NAME"),"") | C15: =IFERROR(_xll.BDP(A15,"EQY_SH_OUT"),NA()) | D15: =IFERROR(_xll.BDH(A15,"EQY_SH_OUT","-"&Settings!$B$4&"AW","-"&Settings!$B$4&"AW","days=a","fill=p"),NA()) | E15: =IFERROR((C15-D15)/D15,NA()) | F15: =IF(ISNUMBER(E15),IF(E15<=Settings!$B$6,"BUYBACK ACTIVITY",""),"") | G15: =IFERROR(_xll.BDP(A15,"VOLUME_AVG_30D"),NA()) | H15: =IFERROR(_xll.BDP(A15,"PX_VOLUME"),NA()) | I15: =IFERROR(H15/G15,NA()) | J15: =IF(ISNUMBER(I15),IF(I15>=Settings!$B$7,"VOL SPIKE",""),"")
... A33: ='STI30 Universe'!A34 | B33: =IFERROR(_xll.BDP(A33,"NAME"),"") | C33: =IFERROR(_xll.BDP(A33,"EQY_SH_OUT"),NA()) | D33: =IFERROR(_xll.BDH(A33,"EQY_SH_OUT","-"&Settings!$B$4&"AW","-"&Settings!$B$4&"AW","days=a","fill=p"),NA()) | E33: =IFERROR((C33-D33)/D33,NA()) | F33: =IF(ISNUMBER(E33),IF(E33<=Settings!$B$6,"BUYBACK ACTIVITY",""),"") | G33: =IFERROR(_xll.BDP(A33,"VOLUME_AVG_30D"),NA()) | H33: =IFERROR(_xll.BDP(A33,"PX_VOLUME"),NA()) | I33: =IFERROR(H33/G33,NA()) | J33: =IF(ISNUMBER(I33),IF(I33>=Settings!$B$7,"VOL SPIKE",""),"")

Sheet STI30 Dividends
A1: Dividend & Distribution Tracker — STI Top 30
A3: Ticker | B3: Name | C3: Declared Date | D3: Ex-Date | E3: Div/Unit (SGD) | F3: Dividend Type | G3: In Lookback Window? | H3: Flag
A4: ='STI30 Universe'!A5 | B4: =IFERROR(_xll.BDP(A4,"NAME"),"") | C4: =IF(LEFT((_xll.BDP(A4,"DVD_DECLARED_DT")),4)="#N/A",NA(),(_xll.BDP(A4,"DVD_DECLARED_DT"))) | D4: =IF(LEFT((_xll.BDP(A4,"DVD_EX_DT")),4)="#N/A",NA(),(_xll.BDP(A4,"DVD_EX_DT"))) | E4: =IF(LEFT((_xll.BDP(A4,"DVD_SH_LAST")), 4) = "#N/A", NA(), (_xll.BDP(A4,"DVD_SH_LAST"))) | F4: =IF(LEFT((_xll.BDP(A4,"DVD_TYP_LAST")), 4) = "#N/A", NA(), (_xll.BDP(A4,"DVD_TYP_LAST"))) | G4: =IF(ISNUMBER(C4),IF(C4>=Settings!$B$5,"Y","N"),"") | H4: =IF(G4="Y",IF(ISNUMBER(SEARCH("Special",F4)),"SPECIAL DIVIDEND","NEW DIVIDEND"),IF(ISNUMBER(SEARCH("Special",F4)),"SPECIAL DIVIDEND",""))
A5: ='STI30 Universe'!A6 | B5: =IFERROR(_xll.BDP(A5,"NAME"),"") | C5: =IF(LEFT((_xll.BDP(A5,"DVD_DECLARED_DT")),4)="#N/A",NA(),(_xll.BDP(A5,"DVD_DECLARED_DT"))) | D5: =IF(LEFT((_xll.BDP(A5,"DVD_EX_DT")),4)="#N/A",NA(),(_xll.BDP(A5,"DVD_EX_DT"))) | E5: =IF(LEFT((_xll.BDP(A5,"DVD_SH_LAST")), 4) = "#N/A", NA(), (_xll.BDP(A5,"DVD_SH_LAST"))) | F5: =IF(LEFT((_xll.BDP(A5,"DVD_TYP_LAST")), 4) = "#N/A", NA(), (_xll.BDP(A5,"DVD_TYP_LAST"))) | G5: =IF(ISNUMBER(C5),IF(C5>=Settings!$B$5,"Y","N"),"") | H5: =IF(G5="Y",IF(ISNUMBER(SEARCH("Special",F5)),"SPECIAL DIVIDEND","NEW DIVIDEND"),IF(ISNUMBER(SEARCH("Special",F5)),"SPECIAL DIVIDEND",""))
A6: ='STI30 Universe'!A7 | B6: =IFERROR(_xll.BDP(A6,"NAME"),"") | C6: =IF(LEFT((_xll.BDP(A6,"DVD_DECLARED_DT")),4)="#N/A",NA(),(_xll.BDP(A6,"DVD_DECLARED_DT"))) | D6: =IF(LEFT((_xll.BDP(A6,"DVD_EX_DT")),4)="#N/A",NA(),(_xll.BDP(A6,"DVD_EX_DT"))) | E6: =IF(LEFT((_xll.BDP(A6,"DVD_SH_LAST")), 4) = "#N/A", NA(), (_xll.BDP(A6,"DVD_SH_LAST"))) | F6: =IF(LEFT((_xll.BDP(A6,"DVD_TYP_LAST")), 4) = "#N/A", NA(), (_xll.BDP(A6,"DVD_TYP_LAST"))) | G6: =IF(ISNUMBER(C6),IF(C6>=Settings!$B$5,"Y","N"),"") | H6: =IF(G6="Y",IF(ISNUMBER(SEARCH("Special",F6)),"SPECIAL DIVIDEND","NEW DIVIDEND"),IF(ISNUMBER(SEARCH("Special",F6)),"SPECIAL DIVIDEND",""))
A7: ='STI30 Universe'!A8 | B7: =IFERROR(_xll.BDP(A7,"NAME"),"") | C7: =IF(LEFT((_xll.BDP(A7,"DVD_DECLARED_DT")),4)="#N/A",NA(),(_xll.BDP(A7,"DVD_DECLARED_DT"))) | D7: =IF(LEFT((_xll.BDP(A7,"DVD_EX_DT")),4)="#N/A",NA(),(_xll.BDP(A7,"DVD_EX_DT"))) | E7: =IF(LEFT((_xll.BDP(A7,"DVD_SH_LAST")), 4) = "#N/A", NA(), (_xll.BDP(A7,"DVD_SH_LAST"))) | F7: =IF(LEFT((_xll.BDP(A7,"DVD_TYP_LAST")), 4) = "#N/A", NA(), (_xll.BDP(A7,"DVD_TYP_LAST"))) | G7: =IF(ISNUMBER(C7),IF(C7>=Settings!$B$5,"Y","N"),"") | H7: =IF(G7="Y",IF(ISNUMBER(SEARCH("Special",F7)),"SPECIAL DIVIDEND","NEW DIVIDEND"),IF(ISNUMBER(SEARCH("Special",F7)),"SPECIAL DIVIDEND",""))
A8: ='STI30 Universe'!A9 | B8: =IFERROR(_xll.BDP(A8,"NAME"),"") | C8: =IF(LEFT((_xll.BDP(A8,"DVD_DECLARED_DT")),4)="#N/A",NA(),(_xll.BDP(A8,"DVD_DECLARED_DT"))) | D8: =IF(LEFT((_xll.BDP(A8,"DVD_EX_DT")),4)="#N/A",NA(),(_xll.BDP(A8,"DVD_EX_DT"))) | E8: =IF(LEFT((_xll.BDP(A8,"DVD_SH_LAST")), 4) = "#N/A", NA(), (_xll.BDP(A8,"DVD_SH_LAST"))) | F8: =IF(LEFT((_xll.BDP(A8,"DVD_TYP_LAST")), 4) = "#N/A", NA(), (_xll.BDP(A8,"DVD_TYP_LAST"))) | G8: =IF(ISNUMBER(C8),IF(C8>=Settings!$B$5,"Y","N"),"") | H8: =IF(G8="Y",IF(ISNUMBER(SEARCH("Special",F8)),"SPECIAL DIVIDEND","NEW DIVIDEND"),IF(ISNUMBER(SEARCH("Special",F8)),"SPECIAL DIVIDEND",""))
A9: ='STI30 Universe'!A10 | B9: =IFERROR(_xll.BDP(A9,"NAME"),"") | C9: =IF(LEFT((_xll.BDP(A9,"DVD_DECLARED_DT")),4)="#N/A",NA(),(_xll.BDP(A9,"DVD_DECLARED_DT"))) | D9: =IF(LEFT((_xll.BDP(A9,"DVD_EX_DT")),4)="#N/A",NA(),(_xll.BDP(A9,"DVD_EX_DT"))) | E9: =IF(LEFT((_xll.BDP(A9,"DVD_SH_LAST")), 4) = "#N/A", NA(), (_xll.BDP(A9,"DVD_SH_LAST"))) | F9: =IF(LEFT((_xll.BDP(A9,"DVD_TYP_LAST")), 4) = "#N/A", NA(), (_xll.BDP(A9,"DVD_TYP_LAST"))) | G9: =IF(ISNUMBER(C9),IF(C9>=Settings!$B$5,"Y","N"),"") | H9: =IF(G9="Y",IF(ISNUMBER(SEARCH("Special",F9)),"SPECIAL DIVIDEND","NEW DIVIDEND"),IF(ISNUMBER(SEARCH("Special",F9)),"SPECIAL DIVIDEND",""))
A10: ='STI30 Universe'!A11 | B10: =IFERROR(_xll.BDP(A10,"NAME"),"") | C10: =IF(LEFT((_xll.BDP(A10,"DVD_DECLARED_DT")),4)="#N/A",NA(),(_xll.BDP(A10,"DVD_DECLARED_DT"))) | D10: =IF(LEFT((_xll.BDP(A10,"DVD_EX_DT")),4)="#N/A",NA(),(_xll.BDP(A10,"DVD_EX_DT"))) | E10: =IF(LEFT((_xll.BDP(A10,"DVD_SH_LAST")), 4) = "#N/A", NA(), (_xll.BDP(A10,"DVD_SH_LAST"))) | F10: =IF(LEFT((_xll.BDP(A10,"DVD_TYP_LAST")), 4) = "#N/A", NA(), (_xll.BDP(A10,"DVD_TYP_LAST"))) | G10: =IF(ISNUMBER(C10),IF(C10>=Settings!$B$5,"Y","N"),"") | H10: =IF(G10="Y",IF(ISNUMBER(SEARCH("Special",F10)),"SPECIAL DIVIDEND","NEW DIVIDEND"),IF(ISNUMBER(SEARCH("Special",F10)),"SPECIAL DIVIDEND",""))
A11: ='STI30 Universe'!A12 | B11: =IFERROR(_xll.BDP(A11,"NAME"),"") | C11: =IF(LEFT((_xll.BDP(A11,"DVD_DECLARED_DT")),4)="#N/A",NA(),(_xll.BDP(A11,"DVD_DECLARED_DT"))) | D11: =IF(LEFT((_xll.BDP(A11,"DVD_EX_DT")),4)="#N/A",NA(),(_xll.BDP(A11,"DVD_EX_DT"))) | E11: =IF(LEFT((_xll.BDP(A11,"DVD_SH_LAST")), 4) = "#N/A", NA(), (_xll.BDP(A11,"DVD_SH_LAST"))) | F11: =IF(LEFT((_xll.BDP(A11,"DVD_TYP_LAST")), 4) = "#N/A", NA(), (_xll.BDP(A11,"DVD_TYP_LAST"))) | G11: =IF(ISNUMBER(C11),IF(C11>=Settings!$B$5,"Y","N"),"") | H11: =IF(G11="Y",IF(ISNUMBER(SEARCH("Special",F11)),"SPECIAL DIVIDEND","NEW DIVIDEND"),IF(ISNUMBER(SEARCH("Special",F11)),"SPECIAL DIVIDEND",""))
A12: ='STI30 Universe'!A13 | B12: =IFERROR(_xll.BDP(A12,"NAME"),"") | C12: =IF(LEFT((_xll.BDP(A12,"DVD_DECLARED_DT")),4)="#N/A",NA(),(_xll.BDP(A12,"DVD_DECLARED_DT"))) | D12: =IF(LEFT((_xll.BDP(A12,"DVD_EX_DT")),4)="#N/A",NA(),(_xll.BDP(A12,"DVD_EX_DT"))) | E12: =IF(LEFT((_xll.BDP(A12,"DVD_SH_LAST")), 4) = "#N/A", NA(), (_xll.BDP(A12,"DVD_SH_LAST"))) | F12: =IF(LEFT((_xll.BDP(A12,"DVD_TYP_LAST")), 4) = "#N/A", NA(), (_xll.BDP(A12,"DVD_TYP_LAST"))) | G12: =IF(ISNUMBER(C12),IF(C12>=Settings!$B$5,"Y","N"),"") | H12: =IF(G12="Y",IF(ISNUMBER(SEARCH("Special",F12)),"SPECIAL DIVIDEND","NEW DIVIDEND"),IF(ISNUMBER(SEARCH("Special",F12)),"SPECIAL DIVIDEND",""))
A13: ='STI30 Universe'!A14 | B13: =IFERROR(_xll.BDP(A13,"NAME"),"") | C13: =IF(LEFT((_xll.BDP(A13,"DVD_DECLARED_DT")),4)="#N/A",NA(),(_xll.BDP(A13,"DVD_DECLARED_DT"))) | D13: =IF(LEFT((_xll.BDP(A13,"DVD_EX_DT")),4)="#N/A",NA(),(_xll.BDP(A13,"DVD_EX_DT"))) | E13: =IF(LEFT((_xll.BDP(A13,"DVD_SH_LAST")), 4) = "#N/A", NA(), (_xll.BDP(A13,"DVD_SH_LAST"))) | F13: =IF(LEFT((_xll.BDP(A13,"DVD_TYP_LAST")), 4) = "#N/A", NA(), (_xll.BDP(A13,"DVD_TYP_LAST"))) | G13: =IF(ISNUMBER(C13),IF(C13>=Settings!$B$5,"Y","N"),"") | H13: =IF(G13="Y",IF(ISNUMBER(SEARCH("Special",F13)),"SPECIAL DIVIDEND","NEW DIVIDEND"),IF(ISNUMBER(SEARCH("Special",F13)),"SPECIAL DIVIDEND",""))
A14: ='STI30 Universe'!A15 | B14: =IFERROR(_xll.BDP(A14,"NAME"),"") | C14: =IF(LEFT((_xll.BDP(A14,"DVD_DECLARED_DT")),4)="#N/A",NA(),(_xll.BDP(A14,"DVD_DECLARED_DT"))) | D14: =IF(LEFT((_xll.BDP(A14,"DVD_EX_DT")),4)="#N/A",NA(),(_xll.BDP(A14,"DVD_EX_DT"))) | E14: =IF(LEFT((_xll.BDP(A14,"DVD_SH_LAST")), 4) = "#N/A", NA(), (_xll.BDP(A14,"DVD_SH_LAST"))) | F14: =IF(LEFT((_xll.BDP(A14,"DVD_TYP_LAST")), 4) = "#N/A", NA(), (_xll.BDP(A14,"DVD_TYP_LAST"))) | G14: =IF(ISNUMBER(C14),IF(C14>=Settings!$B$5,"Y","N"),"") | H14: =IF(G14="Y",IF(ISNUMBER(SEARCH("Special",F14)),"SPECIAL DIVIDEND","NEW DIVIDEND"),IF(ISNUMBER(SEARCH("Special",F14)),"SPECIAL DIVIDEND",""))
A15: ='STI30 Universe'!A16 | B15: =IFERROR(_xll.BDP(A15,"NAME"),"") | C15: =IF(LEFT((_xll.BDP(A15,"DVD_DECLARED_DT")),4)="#N/A",NA(),(_xll.BDP(A15,"DVD_DECLARED_DT"))) | D15: =IF(LEFT((_xll.BDP(A15,"DVD_EX_DT")),4)="#N/A",NA(),(_xll.BDP(A15,"DVD_EX_DT"))) | E15: =IF(LEFT((_xll.BDP(A15,"DVD_SH_LAST")), 4) = "#N/A", NA(), (_xll.BDP(A15,"DVD_SH_LAST"))) | F15: =IF(LEFT((_xll.BDP(A15,"DVD_TYP_LAST")), 4) = "#N/A", NA(), (_xll.BDP(A15,"DVD_TYP_LAST"))) | G15: =IF(ISNUMBER(C15),IF(C15>=Settings!$B$5,"Y","N"),"") | H15: =IF(G15="Y",IF(ISNUMBER(SEARCH("Special",F15)),"SPECIAL DIVIDEND","NEW DIVIDEND"),IF(ISNUMBER(SEARCH("Special",F15)),"SPECIAL DIVIDEND",""))
... A33: ='STI30 Universe'!A34 | B33: =IFERROR(_xll.BDP(A33,"NAME"),"") | C33: =IF(LEFT((_xll.BDP(A33,"DVD_DECLARED_DT")),4)="#N/A",NA(),(_xll.BDP(A33,"DVD_DECLARED_DT"))) | D33: =IF(LEFT((_xll.BDP(A33,"DVD_EX_DT")),4)="#N/A",NA(),(_xll.BDP(A33,"DVD_EX_DT"))) | E33: =IF(LEFT((_xll.BDP(A33,"DVD_SH_LAST")), 4) = "#N/A", NA(), (_xll.BDP(A33,"DVD_SH_LAST"))) | F33: =IF(LEFT((_xll.BDP(A33,"DVD_TYP_LAST")), 4) = "#N/A", NA(), (_xll.BDP(A33,"DVD_TYP_LAST"))) | G33: =IF(ISNUMBER(C33),IF(C33>=Settings!$B$5,"Y","N"),"") | H33: =IF(G33="Y",IF(ISNUMBER(SEARCH("Special",F33)),"SPECIAL DIVIDEND","NEW DIVIDEND"),IF(ISNUMBER(SEARCH("Special",F33)),"SPECIAL DIVIDEND",""))

Sheet STI30 Offerings
A1: Equity Offerings / Splits / Rights Tracker — STI Top 30
A2: Note: columns D–H populate from the live BDS array in column C once opened in Bloomberg Excel and recalculated.
A3: Ticker | B3: Name | C3: Action ID / Details (Bloomberg BDS spill → C:H) | D3: Type of Offering | E3: Announcement Date | F3: Status | G3: Currency | H3: Size | I3: In Lookback Window? | J3: Flag
A4: ='STI30 Universe'!A5 | B4: =IFERROR(_xll.BDP(A4,"NAME"),"") | C4: {=_xll.BDS(A4, "EQUITY_OFFERINGS", "sortdesc=3", "endrow=1")} | I4: =IF(ISNUMBER(E4),IF(E4>=Settings!$B$5,"Y","N"),"") | J4: =IF(I4="Y","RECENT OFFERING/SPLIT/RIGHTS","")
A5: ='STI30 Universe'!A6 | B5: =IFERROR(_xll.BDP(A5,"NAME"),"") | C5: {=_xll.BDS(A5, "EQUITY_OFFERINGS", "sortdesc=3", "endrow=1")} | I5: =IF(ISNUMBER(E5),IF(E5>=Settings!$B$5,"Y","N"),"") | J5: =IF(I5="Y","RECENT OFFERING/SPLIT/RIGHTS","")
A6: ='STI30 Universe'!A7 | B6: =IFERROR(_xll.BDP(A6,"NAME"),"") | C6: {=_xll.BDS(A6, "EQUITY_OFFERINGS", "sortdesc=3", "endrow=1")} | I6: =IF(ISNUMBER(E6),IF(E6>=Settings!$B$5,"Y","N"),"") | J6: =IF(I6="Y","RECENT OFFERING/SPLIT/RIGHTS","")
A7: ='STI30 Universe'!A8 | B7: =IFERROR(_xll.BDP(A7,"NAME"),"") | C7: {=_xll.BDS(A7, "EQUITY_OFFERINGS", "sortdesc=3", "endrow=1")} | I7: =IF(ISNUMBER(E7),IF(E7>=Settings!$B$5,"Y","N"),"") | J7: =IF(I7="Y","RECENT OFFERING/SPLIT/RIGHTS","")
A8: ='STI30 Universe'!A9 | B8: =IFERROR(_xll.BDP(A8,"NAME"),"") | C8: {=_xll.BDS(A8, "EQUITY_OFFERINGS", "sortdesc=3", "endrow=1")} | I8: =IF(ISNUMBER(E8),IF(E8>=Settings!$B$5,"Y","N"),"") | J8: =IF(I8="Y","RECENT OFFERING/SPLIT/RIGHTS","")
A9: ='STI30 Universe'!A10 | B9: =IFERROR(_xll.BDP(A9,"NAME"),"") | C9: {=_xll.BDS(A9, "EQUITY_OFFERINGS", "sortdesc=3", "endrow=1")} | I9: =IF(ISNUMBER(E9),IF(E9>=Settings!$B$5,"Y","N"),"") | J9: =IF(I9="Y","RECENT OFFERING/SPLIT/RIGHTS","")
A10: ='STI30 Universe'!A11 | B10: =IFERROR(_xll.BDP(A10,"NAME"),"") | C10: {=_xll.BDS(A10, "EQUITY_OFFERINGS", "sortdesc=3", "endrow=1")} | I10: =IF(ISNUMBER(E10),IF(E10>=Settings!$B$5,"Y","N"),"") | J10: =IF(I10="Y","RECENT OFFERING/SPLIT/RIGHTS","")
A11: ='STI30 Universe'!A12 | B11: =IFERROR(_xll.BDP(A11,"NAME"),"") | C11: {=_xll.BDS(A11, "EQUITY_OFFERINGS", "sortdesc=3", "endrow=1")} | I11: =IF(ISNUMBER(E11),IF(E11>=Settings!$B$5,"Y","N"),"") | J11: =IF(I11="Y","RECENT OFFERING/SPLIT/RIGHTS","")
A12: ='STI30 Universe'!A13 | B12: =IFERROR(_xll.BDP(A12,"NAME"),"") | C12: {=_xll.BDS(A12, "EQUITY_OFFERINGS", "sortdesc=3", "endrow=1")} | I12: =IF(ISNUMBER(E12),IF(E12>=Settings!$B$5,"Y","N"),"") | J12: =IF(I12="Y","RECENT OFFERING/SPLIT/RIGHTS","")
A13: ='STI30 Universe'!A14 | B13: =IFERROR(_xll.BDP(A13,"NAME"),"") | C13: {=_xll.BDS(A13, "EQUITY_OFFERINGS", "sortdesc=3", "endrow=1")} | I13: =IF(ISNUMBER(E13),IF(E13>=Settings!$B$5,"Y","N"),"") | J13: =IF(I13="Y","RECENT OFFERING/SPLIT/RIGHTS","")
A14: ='STI30 Universe'!A15 | B14: =IFERROR(_xll.BDP(A14,"NAME"),"") | C14: {=_xll.BDS(A14, "EQUITY_OFFERINGS", "sortdesc=3", "endrow=1")} | I14: =IF(ISNUMBER(E14),IF(E14>=Settings!$B$5,"Y","N"),"") | J14: =IF(I14="Y","RECENT OFFERING/SPLIT/RIGHTS","")
A15: ='STI30 Universe'!A16 | B15: =IFERROR(_xll.BDP(A15,"NAME"),"") | C15: {=_xll.BDS(A15, "EQUITY_OFFERINGS", "sortdesc=3", "endrow=1")} | I15: =IF(ISNUMBER(E15),IF(E15>=Settings!$B$5,"Y","N"),"") | J15: =IF(I15="Y","RECENT OFFERING/SPLIT/RIGHTS","")
... A33: ='STI30 Universe'!A34 | B33: =IFERROR(_xll.BDP(A33,"NAME"),"") | C33: {=_xll.BDS(A33, "EQUITY_OFFERINGS", "sortdesc=3", "endrow=1")} | I33: =IF(ISNUMBER(E33),IF(E33>=Settings!$B$5,"Y","N"),"") | J33: =IF(I33="Y","RECENT OFFERING/SPLIT/RIGHTS","")

Sheet Rest Dashboard
A1: CORPORATE ACTIONS DASHBOARD — SGX EX-STI30
A3: Ticker | B3: Name | C3: Buyback Flag | D3: Volume Flag | E3: Dividend Flag | F3: Split/Rights Flag | H3: SHARE BUYBACK AGGREGATOR
A4: ='Rest Universe'!A5 | B4: ='Rest Universe'!B5 | C4: ='Rest Buybacks'!F4 | D4: ='Rest Buybacks'!J4 | E4: ='Rest Dividends'!H4 | F4: ='Rest Offerings'!J4 | H4: Number of Trading Days of Lookback | L4: 30
A5: ='Rest Universe'!A6 | B5: ='Rest Universe'!B6 | C5: ='Rest Buybacks'!F5 | D5: ='Rest Buybacks'!J5 | E5: ='Rest Dividends'!H5 | F5: ='Rest Offerings'!J5 | H5: Company Ticker | L5: ST SP Equity
A6: ='Rest Universe'!A7 | B6: ='Rest Universe'!B7 | C6: ='Rest Buybacks'!F6 | D6: ='Rest Buybacks'!J6 | E6: ='Rest Dividends'!H6 | F6: ='Rest Offerings'!J6 | H6: Company Name | L6: =_xll.BDP(L5,"NAME")
A7: ='Rest Universe'!A8 | B7: ='Rest Universe'!B8 | C7: ='Rest Buybacks'!F7 | D7: ='Rest Buybacks'!J7 | E7: ='Rest Dividends'!H7 | F7: ='Rest Offerings'!J7 | H7: Buyback Amount | L7: =_xll.BQL(L5, "sum(share_buybacks(effective_date=range(-" & L4 &"D, 0D)))", "currency", "SGD")
A8: ='Rest Universe'!A9 | B8: ='Rest Universe'!B9 | C8: ='Rest Buybacks'!F8 | D8: ='Rest Buybacks'!J8 | E8: ='Rest Dividends'!H8 | F8: ='Rest Offerings'!J8
A9: ='Rest Universe'!A10 | B9: ='Rest Universe'!B10 | C9: ='Rest Buybacks'!F9 | D9: ='Rest Buybacks'!J9 | E9: ='Rest Dividends'!H9 | F9: ='Rest Offerings'!J9
A10: ='Rest Universe'!A11 | B10: ='Rest Universe'!B11 | C10: ='Rest Buybacks'!F10 | D10: ='Rest Buybacks'!J10 | E10: ='Rest Dividends'!H10 | F10: ='Rest Offerings'!J10
A11: ='Rest Universe'!A12 | B11: ='Rest Universe'!B12 | C11: ='Rest Buybacks'!F11 | D11: ='Rest Buybacks'!J11 | E11: ='Rest Dividends'!H11 | F11: ='Rest Offerings'!J11
A12: ='Rest Universe'!A13 | B12: ='Rest Universe'!B13 | C12: ='Rest Buybacks'!F12 | D12: ='Rest Buybacks'!J12 | E12: ='Rest Dividends'!H12 | F12: ='Rest Offerings'!J12
A13: ='Rest Universe'!A14 | B13: ='Rest Universe'!B14 | C13: ='Rest Buybacks'!F13 | D13: ='Rest Buybacks'!J13 | E13: ='Rest Dividends'!H13 | F13: ='Rest Offerings'!J13
A14: ='Rest Universe'!A15 | B14: ='Rest Universe'!B15 | C14: ='Rest Buybacks'!F14 | D14: ='Rest Buybacks'!J14 | E14: ='Rest Dividends'!H14 | F14: ='Rest Offerings'!J14
A15: ='Rest Universe'!A16 | B15: ='Rest Universe'!B16 | C15: ='Rest Buybacks'!F15 | D15: ='Rest Buybacks'!J15 | E15: ='Rest Dividends'!H15 | F15: ='Rest Offerings'!J15
A16: ='Rest Universe'!A17 | B16: ='Rest Universe'!B17 | C16: ='Rest Buybacks'!F16 | D16: ='Rest Buybacks'!J16 | E16: ='Rest Dividends'!H16 | F16: ='Rest Offerings'!J16
A17: ='Rest Universe'!A18 | B17: ='Rest Universe'!B18 | C17: ='Rest Buybacks'!F17 | D17: ='Rest Buybacks'!J17 | E17: ='Rest Dividends'!H17 | F17: ='Rest Offerings'!J17
A18: ='Rest Universe'!A19 | B18: ='Rest Universe'!B19 | C18: ='Rest Buybacks'!F18 | D18: ='Rest Buybacks'!J18 | E18: ='Rest Dividends'!H18 | F18: ='Rest Offerings'!J18
A19: ='Rest Universe'!A20 | B19: ='Rest Universe'!B20 | C19: ='Rest Buybacks'!F19 | D19: ='Rest Buybacks'!J19 | E19: ='Rest Dividends'!H19 | F19: ='Rest Offerings'!J19
... A590: ='Rest Universe'!A591 | B590: ='Rest Universe'!B591 | C590: ='Rest Buybacks'!F590 | D590: ='Rest Buybacks'!J590 | E590: ='Rest Dividends'!H590 | F590: ='Rest Offerings'!J590

Sheet Rest Universe
A1: Universe — SGX Ex-STI30
A3: Ticker (Bloomberg) | B3: Company Name | C3: Market Cap | D3: GICS Sector | E3: Primary Exchange
A4: (static snapshot from source Universe tab — re-run your BQL universe pull to refresh tickers/names/sectors)
A5: GE SP Equity | B5: Great Eastern Holdings Ltd | C5: 1.9673436e+10 | D5: Financials | E5: Singapore
A6: JCNC SP Equity | B6: Jardine Cycle & Carriage Ltd | C6: 1.0762284e+10 | D6: Industrials | E6: Singapore
A7: FR SP Equity | B7: First Resources Ltd | C7: 7.1059664e+09 | D7: Consumer Staples | E7: Singapore
A8: SSG SP Equity | B8: Sheng Siong Group Ltd | C8: 4886495250 | D8: Consumer Staples | E8: Singapore
A9: SPLG SP Equity | B9: Singapore Land Group Ltd | C9: 4.6143554e+09 | D9: Real Estate | E9: Singapore
A10: KREIT SP Equity | B10: Keppel REIT | C10: 4.1831601e+09 | D10: Real Estate | E10: Singapore
A11: GGR SP Equity | B11: Golden Agri-Resources Ltd | C11: 4.1215436e+09 | D11: Consumer Staples | E11: Singapore
A12: SUN SP Equity | B12: Suntec Real Estate Investment | C12: 4.087217e+09 | D12: Real Estate | E12: Singapore
A13: STTF SP Equity | B13: State Street SPDR Straits Time | C13: 4.0574577e+09 | D13: #N/A | E13: Singapore
A14: UOBK SP Equity | B14: UOB-Kay Hian Holdings Ltd | C14: 3.9465951e+09 | D14: Financials | E14: Singapore
A15: FPL SP Equity | B15: Frasers Property Ltd | C15: 3.9064114e+09 | D15: Real Estate | E15: Singapore
A16: OLG SP Equity | B16: Olam Group Ltd | C16: 3.8842836e+09 | D16: Consumer Staples | E16: Singapore
A17: BAL SP Equity | B17: Bumitama Agri Ltd | C17: 3.7630927e+09 | D17: Consumer Staples | E17: Singapore
A18: NETLINK SP Equity | B18: NETLINK NBN TRUST | C18: 3.7410922e+09 | D18: Communication Services | E18: Singapore
A19: SIE SP Equity | B19: SIA Engineering Co Ltd | C19: 3.4721593e+09 | D19: Industrials | E19: Singapore
A20: CLAS SP Equity | B20: CapitaLand Ascott Trust | C20: 3.2009806e+09 | D20: Real Estate | E20: Singapore
A21: KIT SP Equity | B21: Keppel Infrastructure Trust | C21: 3.1649004e+09 | D21: Materials | E21: Singapore
A22: HPAR SP Equity | B22: Haw Par Corp Ltd | C22: 2.9928978e+09 | D22: Health Care | E22: Singapore
A23: AEM SP Equity | B23: AEM Holdings Ltd | C23: 2.9616369e+09 | D23: Information Technology | E23: Singapore
A24: CD SP Equity | B24: ComfortDelGro Corp Ltd | C24: 2.7507927e+09 | D24: Industrials | E24: Singapore
A25: IFAST SP Equity | B25: iFAST Corp Ltd | C25: 2.7468442e+09 | D25: Financials | E25: Singapore
... A36: STH SP Equity | B36: StarHub Ltd | C36: 1.899142e+09 | D36: Communication Services | E36: Singapore
A37: DBSSTI SP Equity | B37: Amova Singapore STI ETF | C37: 1.8591392e+09 | D37: #N/A | E37: Singapore
A38: LREIT SP Equity | B38: Lendlease Global Commercial RE | C38: 1.7965959e+09 | D38: Real Estate | E38: Singapore
A39: EREIT SP Equity | B39: ESR-REIT | C39: 1.7729703e+09 | D39: Real Estate | E39: Singapore
A40: HG SP Equity | B40: Hour Glass Ltd/The | C40: 1.7702661e+09 | D40: Consumer Discretionary | E40: Singapore
A41: RFMD SP Equity | B41: Raffles Medical Group Ltd | C41: 1.5506278e+09 | D41: Health Care | E41: Singapore
A42: TMG SP Equity | B42: Thomson Medical Group Ltd | C42: 1.4279553e+09 | D42: Health Care | E42: Singapore
A43: FEH SP Equity | B43: Food Empire Holdings Ltd | C43: 1.4078596e+09 | D43: Consumer Staples | E43: Singapore
A44: CLINT SP Equity | B44: Capitaland India Trust | C44: 1.3921709e+09 | D44: Real Estate | E44: Singapore
A45: HOBEE SP Equity | B45: Ho Bee Land Ltd | C45: 1.3545934e+09 | D45: Real Estate | E45: Singapore
A46: PROP SP Equity | B46: Propnex Ltd | C46: 1.3172e+09 | D46: Real Estate | E46: Singapore
A47: PAC SP Equity | B47: Pacific Century Regional Devel | C47: 1.2967351e+09 | D47: Financials | E47: Singapore
A48: CENT SP Equity | B48: Centurion Corp Ltd | C48: 1.2779835e+09 | D48: Real Estate | E48: Singapore
A49: SERT SP Equity | B49: Stoneweg Europe Stapled Trust | C49: 1.2210707e+09 | D49: Real Estate | E49: Singapore
... A60: BRC SP Equity | B60: BRC Asia Ltd | C60: 1.1495269e+09 | D60: Industrials | E60: Singapore
A61: SBIF SP Equity | B61: ABF Singapore Bond Index Fund | C61: 1.1384835e+09 | D61: #N/A | E61: Singapore
...

Sheet Rest Buybacks
A1: Share Buyback Tracker — SGX Ex-STI30
A3: Ticker | B3: Company Name | C3: Shares Out Today | D3: =CONCATENATE("Shares Out ",Settings!B4, IF(Settings!B4>1," Wks Ago"," Wk Ago")) | E3: % Change | F3: Buyback Flag | G3: Avg Vol (30D) | H3: Volume — Today | I3: Vol vs Avg (x) | J3: Volume Flag
A4: ='Rest Universe'!A5 | B4: =IFERROR(_xll.BDP(A4,"NAME"),"") | C4: =IFERROR(_xll.BDP(A4,"EQY_SH_OUT"),NA()) | D4: =IFERROR(_xll.BDH(A4,"EQY_SH_OUT","-"&Settings!$B$4&"AW","-"&Settings!$B$4&"AW","days=a","fill=p"),NA()) | E4: =IFERROR((C4-D4)/D4,NA()) | F4: =IF(ISNUMBER(E4),IF(E4<=Settings!$B$6,"BUYBACK ACTIVITY",""),"") | G4: =IFERROR(_xll.BDP(A4,"VOLUME_AVG_30D"),NA()) | H4: =IFERROR(_xll.BDP(A4,"PX_VOLUME"),NA()) | I4: =IFERROR(H4/G4,NA()) | J4: =IF(ISNUMBER(I4),IF(I4>=Settings!$B$7,"VOL SPIKE",""),"")
A5: ='Rest Universe'!A6 | B5: =IFERROR(_xll.BDP(A5,"NAME"),"") | C5: =IFERROR(_xll.BDP(A5,"EQY_SH_OUT"),NA()) | D5: =IFERROR(_xll.BDH(A5,"EQY_SH_OUT","-"&Settings!$B$4&"AW","-"&Settings!$B$4&"AW","days=a","fill=p"),NA()) | E5: =IFERROR((C5-D5)/D5,NA()) | F5: =IF(ISNUMBER(E5),IF(E5<=Settings!$B$6,"BUYBACK ACTIVITY",""),"") | G5: =IFERROR(_xll.BDP(A5,"VOLUME_AVG_30D"),NA()) | H5: =IFERROR(_xll.BDP(A5,"PX_VOLUME"),NA()) | I5: =IFERROR(H5/G5,NA()) | J5: =IF(ISNUMBER(I5),IF(I5>=Settings!$B$7,"VOL SPIKE",""),"")
A6: ='Rest Universe'!A7 | B6: =IFERROR(_xll.BDP(A6,"NAME"),"") | C6: =IFERROR(_xll.BDP(A6,"EQY_SH_OUT"),NA()) | D6: =IFERROR(_xll.BDH(A6,"EQY_SH_OUT","-"&Settings!$B$4&"AW","-"&Settings!$B$4&"AW","days=a","fill=p"),NA()) | E6: =IFERROR((C6-D6)/D6,NA()) | F6: =IF(ISNUMBER(E6),IF(E6<=Settings!$B$6,"BUYBACK ACTIVITY",""),"") | G6: =IFERROR(_xll.BDP(A6,"VOLUME_AVG_30D"),NA()) | H6: =IFERROR(_xll.BDP(A6,"PX_VOLUME"),NA()) | I6: =IFERROR(H6/G6,NA()) | J6: =IF(ISNUMBER(I6),IF(I6>=Settings!$B$7,"VOL SPIKE",""),"")
A7: ='Rest Universe'!A8 | B7: =IFERROR(_xll.BDP(A7,"NAME"),"") | C7: =IFERROR(_xll.BDP(A7,"EQY_SH_OUT"),NA()) | D7: =IFERROR(_xll.BDH(A7,"EQY_SH_OUT","-"&Settings!$B$4&"AW","-"&Settings!$B$4&"AW","days=a","fill=p"),NA()) | E7: =IFERROR((C7-D7)/D7,NA()) | F7: =IF(ISNUMBER(E7),IF(E7<=Settings!$B$6,"BUYBACK ACTIVITY",""),"") | G7: =IFERROR(_xll.BDP(A7,"VOLUME_AVG_30D"),NA()) | H7: =IFERROR(_xll.BDP(A7,"PX_VOLUME"),NA()) | I7: =IFERROR(H7/G7,NA()) | J7: =IF(ISNUMBER(I7),IF(I7>=Settings!$B$7,"VOL SPIKE",""),"")
A8: ='Rest Universe'!A9 | B8: =IFERROR(_xll.BDP(A8,"NAME"),"") | C8: =IFERROR(_xll.BDP(A8,"EQY_SH_OUT"),NA()) | D8: =IFERROR(_xll.BDH(A8,"EQY_SH_OUT","-"&Settings!$B$4&"AW","-"&Settings!$B$4&"AW","days=a","fill=p"),NA()) | E8: =IFERROR((C8-D8)/D8,NA()) | F8: =IF(ISNUMBER(E8),IF(E8<=Settings!$B$6,"BUYBACK ACTIVITY",""),"") | G8: =IFERROR(_xll.BDP(A8,"VOLUME_AVG_30D"),NA()) | H8: =IFERROR(_xll.BDP(A8,"PX_VOLUME"),NA()) | I8: =IFERROR(H8/G8,NA()) | J8: =IF(ISNUMBER(I8),IF(I8>=Settings!$B$7,"VOL SPIKE",""),"")
A9: ='Rest Universe'!A10 | B9: =IFERROR(_xll.BDP(A9,"NAME"),"") | C9: =IFERROR(_xll.BDP(A9,"EQY_SH_OUT"),NA()) | D9: =IFERROR(_xll.BDH(A9,"EQY_SH_OUT","-"&Settings!$B$4&"AW","-"&Settings!$B$4&"AW","days=a","fill=p"),NA()) | E9: =IFERROR((C9-D9)/D9,NA()) | F9: =IF(ISNUMBER(E9),IF(E9<=Settings!$B$6,"BUYBACK ACTIVITY",""),"") | G9: =IFERROR(_xll.BDP(A9,"VOLUME_AVG_30D"),NA()) | H9: =IFERROR(_xll.BDP(A9,"PX_VOLUME"),NA()) | I9: =IFERROR(H9/G9,NA()) | J9: =IF(ISNUMBER(I9),IF(I9>=Settings!$B$7,"VOL SPIKE",""),"")
A10: ='Rest Universe'!A11 | B10: =IFERROR(_xll.BDP(A10,"NAME"),"") | C10: =IFERROR(_xll.BDP(A10,"EQY_SH_OUT"),NA()) | D10: =IFERROR(_xll.BDH(A10,"EQY_SH_OUT","-"&Settings!$B$4&"AW","-"&Settings!$B$4&"AW","days=a","fill=p"),NA()) | E10: =IFERROR((C10-D10)/D10,NA()) | F10: =IF(ISNUMBER(E10),IF(E10<=Settings!$B$6,"BUYBACK ACTIVITY",""),"") | G10: =IFERROR(_xll.BDP(A10,"VOLUME_AVG_30D"),NA()) | H10: =IFERROR(_xll.BDP(A10,"PX_VOLUME"),NA()) | I10: =IFERROR(H10/G10,NA()) | J10: =IF(ISNUMBER(I10),IF(I10>=Settings!$B$7,"VOL SPIKE",""),"")
A11: ='Rest Universe'!A12 | B11: =IFERROR(_xll.BDP(A11,"NAME"),"") | C11: =IFERROR(_xll.BDP(A11,"EQY_SH_OUT"),NA()) | D11: =IFERROR(_xll.BDH(A11,"EQY_SH_OUT","-"&Settings!$B$4&"AW","-"&Settings!$B$4&"AW","days=a","fill=p"),NA()) | E11: =IFERROR((C11-D11)/D11,NA()) | F11: =IF(ISNUMBER(E11),IF(E11<=Settings!$B$6,"BUYBACK ACTIVITY",""),"") | G11: =IFERROR(_xll.BDP(A11,"VOLUME_AVG_30D"),NA()) | H11: =IFERROR(_xll.BDP(A11,"PX_VOLUME"),NA()) | I11: =IFERROR(H11/G11,NA()) | J11: =IF(ISNUMBER(I11),IF(I11>=Settings!$B$7,"VOL SPIKE",""),"")
A12: ='Rest Universe'!A13 | B12: =IFERROR(_xll.BDP(A12,"NAME"),"") | C12: =IFERROR(_xll.BDP(A12,"EQY_SH_OUT"),NA()) | D12: =IFERROR(_xll.BDH(A12,"EQY_SH_OUT","-"&Settings!$B$4&"AW","-"&Settings!$B$4&"AW","days=a","fill=p"),NA()) | E12: =IFERROR((C12-D12)/D12,NA()) | F12: =IF(ISNUMBER(E12),IF(E12<=Settings!$B$6,"BUYBACK ACTIVITY",""),"") | G12: =IFERROR(_xll.BDP(A12,"VOLUME_AVG_30D"),NA()) | H12: =IFERROR(_xll.BDP(A12,"PX_VOLUME"),NA()) | I12: =IFERROR(H12/G12,NA()) | J12: =IF(ISNUMBER(I12),IF(I12>=Settings!$B$7,"VOL SPIKE",""),"")
A13: ='Rest Universe'!A14 | B13: =IFERROR(_xll.BDP(A13,"NAME"),"") | C13: =IFERROR(_xll.BDP(A13,"EQY_SH_OUT"),NA()) | D13: =IFERROR(_xll.BDH(A13,"EQY_SH_OUT","-"&Settings!$B$4&"AW","-"&Settings!$B$4&"AW","days=a","fill=p"),NA()) | E13: =IFERROR((C13-D13)/D13,NA()) | F13: =IF(ISNUMBER(E13),IF(E13<=Settings!$B$6,"BUYBACK ACTIVITY",""),"") | G13: =IFERROR(_xll.BDP(A13,"VOLUME_AVG_30D"),NA()) | H13: =IFERROR(_xll.BDP(A13,"PX_VOLUME"),NA()) | I13: =IFERROR(H13/G13,NA()) | J13: =IF(ISNUMBER(I13),IF(I13>=Settings!$B$7,"VOL SPIKE",""),"")
A14: ='Rest Universe'!A15 | B14: =IFERROR(_xll.BDP(A14,"NAME"),"") | C14: =IFERROR(_xll.BDP(A14,"EQY_SH_OUT"),NA()) | D14: =IFERROR(_xll.BDH(A14,"EQY_SH_OUT","-"&Settings!$B$4&"AW","-"&Settings!$B$4&"AW","days=a","fill=p"),NA()) | E14: =IFERROR((C14-D14)/D14,NA()) | F14: =IF(ISNUMBER(E14),IF(E14<=Settings!$B$6,"BUYBACK ACTIVITY",""),"") | G14: =IFERROR(_xll.BDP(A14,"VOLUME_AVG_30D"),NA()) | H14: =IFERROR(_xll.BDP(A14,"PX_VOLUME"),NA()) | I14: =IFERROR(H14/G14,NA()) | J14: =IF(ISNUMBER(I14),IF(I14>=Settings!$B$7,"VOL SPIKE",""),"")
A15: ='Rest Universe'!A16 | B15: =IFERROR(_xll.BDP(A15,"NAME"),"") | C15: =IFERROR(_xll.BDP(A15,"EQY_SH_OUT"),NA()) | D15: =IFERROR(_xll.BDH(A15,"EQY_SH_OUT","-"&Settings!$B$4&"AW","-"&Settings!$B$4&"AW","days=a","fill=p"),NA()) | E15: =IFERROR((C15-D15)/D15,NA()) | F15: =IF(ISNUMBER(E15),IF(E15<=Settings!$B$6,"BUYBACK ACTIVITY",""),"") | G15: =IFERROR(_xll.BDP(A15,"VOLUME_AVG_30D"),NA()) | H15: =IFERROR(_xll.BDP(A15,"PX_VOLUME"),NA()) | I15: =IFERROR(H15/G15,NA()) | J15: =IF(ISNUMBER(I15),IF(I15>=Settings!$B$7,"VOL SPIKE",""),"")
... A590: ='Rest Universe'!A591 | B590: =IFERROR(_xll.BDP(A590,"NAME"),"") | C590: =IFERROR(_xll.BDP(A590,"EQY_SH_OUT"),NA()) | D590: =IFERROR(_xll.BDH(A590,"EQY_SH_OUT","-"&Settings!$B$4&"AW","-"&Settings!$B$4&"AW","days=a","fill=p"),NA()) | E590: =IFERROR((C590-D590)/D590,NA()) | F590: =IF(ISNUMBER(E590),IF(E590<=Settings!$B$6,"BUYBACK ACTIVITY",""),"") | G590: =IFERROR(_xll.BDP(A590,"VOLUME_AVG_30D"),NA()) | H590: =IFERROR(_xll.BDP(A590,"PX_VOLUME"),NA()) | I590: =IFERROR(H590/G590,NA()) | J590: =IF(ISNUMBER(I590),IF(I590>=Settings!$B$7,"VOL SPIKE",""),"")

Sheet Rest Dividends
A1: Dividend & Distribution Tracker — SGX Ex-STI30
A3: Ticker | B3: Name | C3: Declared Date | D3: Ex-Date | E3: Div/Unit (SGD) | F3: Dividend Type | G3: In Lookback Window? | H3: Flag
A4: ='Rest Universe'!A5 | B4: =IFERROR(_xll.BDP(A4,"NAME"),"") | C4: =IF(LEFT((_xll.BDP(A4,"DVD_DECLARED_DT")),4)="#N/A",NA(),(_xll.BDP(A4,"DVD_DECLARED_DT"))) | D4: =IF(LEFT((_xll.BDP(A4,"DVD_EX_DT")),4)="#N/A",NA(),(_xll.BDP(A4,"DVD_EX_DT"))) | E4: =IF(LEFT((_xll.BDP(A4,"DVD_SH_LAST")), 4) = "#N/A", NA(), (_xll.BDP(A4,"DVD_SH_LAST"))) | F4: =IF(LEFT((_xll.BDP(A4,"DVD_TYP_LAST")), 4) = "#N/A", NA(), (_xll.BDP(A4,"DVD_TYP_LAST"))) | G4: =IF(ISNUMBER(C4),IF(C4>=Settings!$B$5,"Y","N"),"") | H4: =IF(G4="Y",IF(ISNUMBER(SEARCH("Special",F4)),"SPECIAL DIVIDEND","NEW DIVIDEND"),IF(ISNUMBER(SEARCH("Special",F4)),"SPECIAL DIVIDEND",""))
A5: ='Rest Universe'!A6 | B5: =IFERROR(_xll.BDP(A5,"NAME"),"") | C5: =IF(LEFT((_xll.BDP(A5,"DVD_DECLARED_DT")),4)="#N/A",NA(),(_xll.BDP(A5,"DVD_DECLARED_DT"))) | D5: =IF(LEFT((_xll.BDP(A5,"DVD_EX_DT")),4)="#N/A",NA(),(_xll.BDP(A5,"DVD_EX_DT"))) | E5: =IF(LEFT((_xll.BDP(A5,"DVD_SH_LAST")), 4) = "#N/A", NA(), (_xll.BDP(A5,"DVD_SH_LAST"))) | F5: =IF(LEFT((_xll.BDP(A5,"DVD_TYP_LAST")), 4) = "#N/A", NA(), (_xll.BDP(A5,"DVD_TYP_LAST"))) | G5: =IF(ISNUMBER(C5),IF(C5>=Settings!$B$5,"Y","N"),"") | H5: =IF(G5="Y",IF(ISNUMBER(SEARCH("Special",F5)),"SPECIAL DIVIDEND","NEW DIVIDEND"),IF(ISNUMBER(SEARCH("Special",F5)),"SPECIAL DIVIDEND",""))
A6: ='Rest Universe'!A7 | B6: =IFERROR(_xll.BDP(A6,"NAME"),"") | C6: =IF(LEFT((_xll.BDP(A6,"DVD_DECLARED_DT")),4)="#N/A",NA(),(_xll.BDP(A6,"DVD_DECLARED_DT"))) | D6: =IF(LEFT((_xll.BDP(A6,"DVD_EX_DT")),4)="#N/A",NA(),(_xll.BDP(A6,"DVD_EX_DT"))) | E6: =IF(LEFT((_xll.BDP(A6,"DVD_SH_LAST")), 4) = "#N/A", NA(), (_xll.BDP(A6,"DVD_SH_LAST"))) | F6: =IF(LEFT((_xll.BDP(A6,"DVD_TYP_LAST")), 4) = "#N/A", NA(), (_xll.BDP(A6,"DVD_TYP_LAST"))) | G6: =IF(ISNUMBER(C6),IF(C6>=Settings!$B$5,"Y","N"),"") | H6: =IF(G6="Y",IF(ISNUMBER(SEARCH("Special",F6)),"SPECIAL DIVIDEND","NEW DIVIDEND"),IF(ISNUMBER(SEARCH("Special",F6)),"SPECIAL DIVIDEND",""))
A7: ='Rest Universe'!A8 | B7: =IFERROR(_xll.BDP(A7,"NAME"),"") | C7: =IF(LEFT((_xll.BDP(A7,"DVD_DECLARED_DT")),4)="#N/A",NA(),(_xll.BDP(A7,"DVD_DECLARED_DT"))) | D7: =IF(LEFT((_xll.BDP(A7,"DVD_EX_DT")),4)="#N/A",NA(),(_xll.BDP(A7,"DVD_EX_DT"))) | E7: =IF(LEFT((_xll.BDP(A7,"DVD_SH_LAST")), 4) = "#N/A", NA(), (_xll.BDP(A7,"DVD_SH_LAST"))) | F7: =IF(LEFT((_xll.BDP(A7,"DVD_TYP_LAST")), 4) = "#N/A", NA(), (_xll.BDP(A7,"DVD_TYP_LAST"))) | G7: =IF(ISNUMBER(C7),IF(C7>=Settings!$B$5,"Y","N"),"") | H7: =IF(G7="Y",IF(ISNUMBER(SEARCH("Special",F7)),"SPECIAL DIVIDEND","NEW DIVIDEND"),IF(ISNUMBER(SEARCH("Special",F7)),"SPECIAL DIVIDEND",""))
A8: ='Rest Universe'!A9 | B8: =IFERROR(_xll.BDP(A8,"NAME"),"") | C8: =IF(LEFT((_xll.BDP(A8,"DVD_DECLARED_DT")),4)="#N/A",NA(),(_xll.BDP(A8,"DVD_DECLARED_DT"))) | D8: =IF(LEFT((_xll.BDP(A8,"DVD_EX_DT")),4)="#N/A",NA(),(_xll.BDP(A8,"DVD_EX_DT"))) | E8: =IF(LEFT((_xll.BDP(A8,"DVD_SH_LAST")), 4) = "#N/A", NA(), (_xll.BDP(A8,"DVD_SH_LAST"))) | F8: =IF(LEFT((_xll.BDP(A8,"DVD_TYP_LAST")), 4) = "#N/A", NA(), (_xll.BDP(A8,"DVD_TYP_LAST"))) | G8: =IF(ISNUMBER(C8),IF(C8>=Settings!$B$5,"Y","N"),"") | H8: =IF(G8="Y",IF(ISNUMBER(SEARCH("Special",F8)),"SPECIAL DIVIDEND","NEW DIVIDEND"),IF(ISNUMBER(SEARCH("Special",F8)),"SPECIAL DIVIDEND",""))
A9: ='Rest Universe'!A10 | B9: =IFERROR(_xll.BDP(A9,"NAME"),"") | C9: =IF(LEFT((_xll.BDP(A9,"DVD_DECLARED_DT")),4)="#N/A",NA(),(_xll.BDP(A9,"DVD_DECLARED_DT"))) | D9: =IF(LEFT((_xll.BDP(A9,"DVD_EX_DT")),4)="#N/A",NA(),(_xll.BDP(A9,"DVD_EX_DT"))) | E9: =IF(LEFT((_xll.BDP(A9,"DVD_SH_LAST")), 4) = "#N/A", NA(), (_xll.BDP(A9,"DVD_SH_LAST"))) | F9: =IF(LEFT((_xll.BDP(A9,"DVD_TYP_LAST")), 4) = "#N/A", NA(), (_xll.BDP(A9,"DVD_TYP_LAST"))) | G9: =IF(ISNUMBER(C9),IF(C9>=Settings!$B$5,"Y","N"),"") | H9: =IF(G9="Y",IF(ISNUMBER(SEARCH("Special",F9)),"SPECIAL DIVIDEND","NEW DIVIDEND"),IF(ISNUMBER(SEARCH("Special",F9)),"SPECIAL DIVIDEND",""))
A10: ='Rest Universe'!A11 | B10: =IFERROR(_xll.BDP(A10,"NAME"),"") | C10: =IF(LEFT((_xll.BDP(A10,"DVD_DECLARED_DT")),4)="#N/A",NA(),(_xll.BDP(A10,"DVD_DECLARED_DT"))) | D10: =IF(LEFT((_xll.BDP(A10,"DVD_EX_DT")),4)="#N/A",NA(),(_xll.BDP(A10,"DVD_EX_DT"))) | E10: =IF(LEFT((_xll.BDP(A10,"DVD_SH_LAST")), 4) = "#N/A", NA(), (_xll.BDP(A10,"DVD_SH_LAST"))) | F10: =IF(LEFT((_xll.BDP(A10,"DVD_TYP_LAST")), 4) = "#N/A", NA(), (_xll.BDP(A10,"DVD_TYP_LAST"))) | G10: =IF(ISNUMBER(C10),IF(C10>=Settings!$B$5,"Y","N"),"") | H10: =IF(G10="Y",IF(ISNUMBER(SEARCH("Special",F10)),"SPECIAL DIVIDEND","NEW DIVIDEND"),IF(ISNUMBER(SEARCH("Special",F10)),"SPECIAL DIVIDEND",""))
A11: ='Rest Universe'!A12 | B11: =IFERROR(_xll.BDP(A11,"NAME"),"") | C11: =IF(LEFT((_xll.BDP(A11,"DVD_DECLARED_DT")),4)="#N/A",NA(),(_xll.BDP(A11,"DVD_DECLARED_DT"))) | D11: =IF(LEFT((_xll.BDP(A11,"DVD_EX_DT")),4)="#N/A",NA(),(_xll.BDP(A11,"DVD_EX_DT"))) | E11: =IF(LEFT((_xll.BDP(A11,"DVD_SH_LAST")), 4) = "#N/A", NA(), (_xll.BDP(A11,"DVD_SH_LAST"))) | F11: =IF(LEFT((_xll.BDP(A11,"DVD_TYP_LAST")), 4) = "#N/A", NA(), (_xll.BDP(A11,"DVD_TYP_LAST"))) | G11: =IF(ISNUMBER(C11),IF(C11>=Settings!$B$5,"Y","N"),"") | H11: =IF(G11="Y",IF(ISNUMBER(SEARCH("Special",F11)),"SPECIAL DIVIDEND","NEW DIVIDEND"),IF(ISNUMBER(SEARCH("Special",F11)),"SPECIAL DIVIDEND",""))
A12: ='Rest Universe'!A13 | B12: =IFERROR(_xll.BDP(A12,"NAME"),"") | C12: =IF(LEFT((_xll.BDP(A12,"DVD_DECLARED_DT")),4)="#N/A",NA(),(_xll.BDP(A12,"DVD_DECLARED_DT"))) | D12: =IF(LEFT((_xll.BDP(A12,"DVD_EX_DT")),4)="#N/A",NA(),(_xll.BDP(A12,"DVD_EX_DT"))) | E12: =IF(LEFT((_xll.BDP(A12,"DVD_SH_LAST")), 4) = "#N/A", NA(), (_xll.BDP(A12,"DVD_SH_LAST"))) | F12: =IF(LEFT((_xll.BDP(A12,"DVD_TYP_LAST")), 4) = "#N/A", NA(), (_xll.BDP(A12,"DVD_TYP_LAST"))) | G12: =IF(ISNUMBER(C12),IF(C12>=Settings!$B$5,"Y","N"),"") | H12: =IF(G12="Y",IF(ISNUMBER(SEARCH("Special",F12)),"SPECIAL DIVIDEND","NEW DIVIDEND"),IF(ISNUMBER(SEARCH("Special",F12)),"SPECIAL DIVIDEND",""))
A13: ='Rest Universe'!A14 | B13: =IFERROR(_xll.BDP(A13,"NAME"),"") | C13: =IF(LEFT((_xll.BDP(A13,"DVD_DECLARED_DT")),4)="#N/A",NA(),(_xll.BDP(A13,"DVD_DECLARED_DT"))) | D13: =IF(LEFT((_xll.BDP(A13,"DVD_EX_DT")),4)="#N/A",NA(),(_xll.BDP(A13,"DVD_EX_DT"))) | E13: =IF(LEFT((_xll.BDP(A13,"DVD_SH_LAST")), 4) = "#N/A", NA(), (_xll.BDP(A13,"DVD_SH_LAST"))) | F13: =IF(LEFT((_xll.BDP(A13,"DVD_TYP_LAST")), 4) = "#N/A", NA(), (_xll.BDP(A13,"DVD_TYP_LAST"))) | G13: =IF(ISNUMBER(C13),IF(C13>=Settings!$B$5,"Y","N"),"") | H13: =IF(G13="Y",IF(ISNUMBER(SEARCH("Special",F13)),"SPECIAL DIVIDEND","NEW DIVIDEND"),IF(ISNUMBER(SEARCH("Special",F13)),"SPECIAL DIVIDEND",""))
A14: ='Rest Universe'!A15 | B14: =IFERROR(_xll.BDP(A14,"NAME"),"") | C14: =IF(LEFT((_xll.BDP(A14,"DVD_DECLARED_DT")),4)="#N/A",NA(),(_xll.BDP(A14,"DVD_DECLARED_DT"))) | D14: =IF(LEFT((_xll.BDP(A14,"DVD_EX_DT")),4)="#N/A",NA(),(_xll.BDP(A14,"DVD_EX_DT"))) | E14: =IF(LEFT((_xll.BDP(A14,"DVD_SH_LAST")), 4) = "#N/A", NA(), (_xll.BDP(A14,"DVD_SH_LAST"))) | F14: =IF(LEFT((_xll.BDP(A14,"DVD_TYP_LAST")), 4) = "#N/A", NA(), (_xll.BDP(A14,"DVD_TYP_LAST"))) | G14: =IF(ISNUMBER(C14),IF(C14>=Settings!$B$5,"Y","N"),"") | H14: =IF(G14="Y",IF(ISNUMBER(SEARCH("Special",F14)),"SPECIAL DIVIDEND","NEW DIVIDEND"),IF(ISNUMBER(SEARCH("Special",F14)),"SPECIAL DIVIDEND",""))
A15: ='Rest Universe'!A16 | B15: =IFERROR(_xll.BDP(A15,"NAME"),"") | C15: =IF(LEFT((_xll.BDP(A15,"DVD_DECLARED_DT")),4)="#N/A",NA(),(_xll.BDP(A15,"DVD_DECLARED_DT"))) | D15: =IF(LEFT((_xll.BDP(A15,"DVD_EX_DT")),4)="#N/A",NA(),(_xll.BDP(A15,"DVD_EX_DT"))) | E15: =IF(LEFT((_xll.BDP(A15,"DVD_SH_LAST")), 4) = "#N/A", NA(), (_xll.BDP(A15,"DVD_SH_LAST"))) | F15: =IF(LEFT((_xll.BDP(A15,"DVD_TYP_LAST")), 4) = "#N/A", NA(), (_xll.BDP(A15,"DVD_TYP_LAST"))) | G15: =IF(ISNUMBER(C15),IF(C15>=Settings!$B$5,"Y","N"),"") | H15: =IF(G15="Y",IF(ISNUMBER(SEARCH("Special",F15)),"SPECIAL DIVIDEND","NEW DIVIDEND"),IF(ISNUMBER(SEARCH("Special",F15)),"SPECIAL DIVIDEND",""))
... A590: ='Rest Universe'!A591 | B590: =IFERROR(_xll.BDP(A590,"NAME"),"") | C590: =IF(LEFT((_xll.BDP(A590,"DVD_DECLARED_DT")),4)="#N/A",NA(),(_xll.BDP(A590,"DVD_DECLARED_DT"))) | D590: =IF(LEFT((_xll.BDP(A590,"DVD_EX_DT")),4)="#N/A",NA(),(_xll.BDP(A590,"DVD_EX_DT"))) | E590: =IF(LEFT((_xll.BDP(A590,"DVD_SH_LAST")), 4) = "#N/A", NA(), (_xll.BDP(A590,"DVD_SH_LAST"))) | F590: =IF(LEFT((_xll.BDP(A590,"DVD_TYP_LAST")), 4) = "#N/A", NA(), (_xll.BDP(A590,"DVD_TYP_LAST"))) | G590: =IF(ISNUMBER(C590),IF(C590>=Settings!$B$5,"Y","N"),"") | H590: =IF(G590="Y",IF(ISNUMBER(SEARCH("Special",F590)),"SPECIAL DIVIDEND","NEW DIVIDEND"),IF(ISNUMBER(SEARCH("Special",F590)),"SPECIAL DIVIDEND",""))

Sheet Rest Offerings
A1: Equity Offerings / Splits / Rights Tracker — SGX Ex-STI30
A2: Note: columns D–H populate from the live BDS array in column C once opened in Bloomberg Excel and recalculated.
A3: Ticker | B3: Name | C3: Action ID / Details (Bloomberg BDS spill → C:H) | D3: Type of Offering | E3: Announcement Date | F3: Status | G3: Currency | H3: Size | I3: In Lookback Window? | J3: Flag
A4: ='Rest Universe'!A5 | B4: =IFERROR(_xll.BDP(A4,"NAME"),"") | C4: {=_xll.BDS(A4, "EQUITY_OFFERINGS", "sortdesc=3", "endrow=1")} | I4: =IF(ISNUMBER(E4),IF(E4>=Settings!$B$5,"Y","N"),"") | J4: =IF(I4="Y","RECENT OFFERING/SPLIT/RIGHTS","")
A5: ='Rest Universe'!A6 | B5: =IFERROR(_xll.BDP(A5,"NAME"),"") | C5: {=_xll.BDS(A5, "EQUITY_OFFERINGS", "sortdesc=3", "endrow=1")} | I5: =IF(ISNUMBER(E5),IF(E5>=Settings!$B$5,"Y","N"),"") | J5: =IF(I5="Y","RECENT OFFERING/SPLIT/RIGHTS","")
A6: ='Rest Universe'!A7 | B6: =IFERROR(_xll.BDP(A6,"NAME"),"") | C6: {=_xll.BDS(A6, "EQUITY_OFFERINGS", "sortdesc=3", "endrow=1")} | I6: =IF(ISNUMBER(E6),IF(E6>=Settings!$B$5,"Y","N"),"") | J6: =IF(I6="Y","RECENT OFFERING/SPLIT/RIGHTS","")
A7: ='Rest Universe'!A8 | B7: =IFERROR(_xll.BDP(A7,"NAME"),"") | C7: {=_xll.BDS(A7, "EQUITY_OFFERINGS", "sortdesc=3", "endrow=1")} | I7: =IF(ISNUMBER(E7),IF(E7>=Settings!$B$5,"Y","N"),"") | J7: =IF(I7="Y","RECENT OFFERING/SPLIT/RIGHTS","")
A8: ='Rest Universe'!A9 | B8: =IFERROR(_xll.BDP(A8,"NAME"),"") | C8: {=_xll.BDS(A8, "EQUITY_OFFERINGS", "sortdesc=3", "endrow=1")} | I8: =IF(ISNUMBER(E8),IF(E8>=Settings!$B$5,"Y","N"),"") | J8: =IF(I8="Y","RECENT OFFERING/SPLIT/RIGHTS","")
A9: ='Rest Universe'!A10 | B9: =IFERROR(_xll.BDP(A9,"NAME"),"") | C9: {=_xll.BDS(A9, "EQUITY_OFFERINGS", "sortdesc=3", "endrow=1")} | I9: =IF(ISNUMBER(E9),IF(E9>=Settings!$B$5,"Y","N"),"") | J9: =IF(I9="Y","RECENT OFFERING/SPLIT/RIGHTS","")
A10: ='Rest Universe'!A11 | B10: =IFERROR(_xll.BDP(A10,"NAME"),"") | C10: {=_xll.BDS(A10, "EQUITY_OFFERINGS", "sortdesc=3", "endrow=1")} | I10: =IF(ISNUMBER(E10),IF(E10>=Settings!$B$5,"Y","N"),"") | J10: =IF(I10="Y","RECENT OFFERING/SPLIT/RIGHTS","")
A11: ='Rest Universe'!A12 | B11: =IFERROR(_xll.BDP(A11,"NAME"),"") | C11: {=_xll.BDS(A11, "EQUITY_OFFERINGS", "sortdesc=3", "endrow=1")} | I11: =IF(ISNUMBER(E11),IF(E11>=Settings!$B$5,"Y","N"),"") | J11: =IF(I11="Y","RECENT OFFERING/SPLIT/RIGHTS","")
A12: ='Rest Universe'!A13 | B12: =IFERROR(_xll.BDP(A12,"NAME"),"") | C12: {=_xll.BDS(A12, "EQUITY_OFFERINGS", "sortdesc=3", "endrow=1")} | I12: =IF(ISNUMBER(E12),IF(E12>=Settings!$B$5,"Y","N"),"") | J12: =IF(I12="Y","RECENT OFFERING/SPLIT/RIGHTS","")
A13: ='Rest Universe'!A14 | B13: =IFERROR(_xll.BDP(A13,"NAME"),"") | C13: {=_xll.BDS(A13, "EQUITY_OFFERINGS", "sortdesc=3", "endrow=1")} | I13: =IF(ISNUMBER(E13),IF(E13>=Settings!$B$5,"Y","N"),"") | J13: =IF(I13="Y","RECENT OFFERING/SPLIT/RIGHTS","")
A14: ='Rest Universe'!A15 | B14: =IFERROR(_xll.BDP(A14,"NAME"),"") | C14: {=_xll.BDS(A14, "EQUITY_OFFERINGS", "sortdesc=3", "endrow=1")} | I14: =IF(ISNUMBER(E14),IF(E14>=Settings!$B$5,"Y","N"),"") | J14: =IF(I14="Y","RECENT OFFERING/SPLIT/RIGHTS","")
A15: ='Rest Universe'!A16 | B15: =IFERROR(_xll.BDP(A15,"NAME"),"") | C15: {=_xll.BDS(A15, "EQUITY_OFFERINGS", "sortdesc=3", "endrow=1")} | I15: =IF(ISNUMBER(E15),IF(E15>=Settings!$B$5,"Y","N"),"") | J15: =IF(I15="Y","RECENT OFFERING/SPLIT/RIGHTS","")
... A590: ='Rest Universe'!A591 | B590: =IFERROR(_xll.BDP(A590,"NAME"),"") | C590: {=_xll.BDS(A590, "EQUITY_OFFERINGS", "sortdesc=3", "endrow=1")} | I590: =IF(ISNUMBER(E590),IF(E590>=Settings!$B$5,"Y","N"),"") | J590: =IF(I590="Y","RECENT OFFERING/SPLIT/RIGHTS","")
